Workbook

Sheet CAPA
B10: PLANILHA DE CONTROLE DE ESTOQUE
D14: Cadastros | E14: Entradas | F14: Saídas | G14: Controle de estoque | H14: Instruções

Sheet Instruções
B1: INSTRUÇÕES | R1: CAPA
B3: Abaixo, você encontra a explicação para todas as abas da planilha.
B4: Saiba mais sobre a importância do controle estoque
B6: ABAS: CADASTRO/ ENTRADAS/ SAÍDAS | C6: As cores das fontes dos valores nas tabelas dessas abas indicam que: (1) Células com fontes na cor PRETA devem ser preenchidas manualmente. (2) Células com fontes na cor AZUL são calculadas automaticamente por fórmulas, portanto NÃO devem ser editadas.
B8: CADASTRO PRODUTOS | C8: OBSERVAÇÃO 1 Esta aba faz parte do conjunto de 3 abas para cadastro de informações. Aqui, você pode cadastrar os dados referentes aos seus PRODUTOS. Esta tabela possui uma Validação de Dados que impede o cadastro de produtos duplicados. OBSERVAÇÃO 2 Para cadastrar um novo PRODUTO, basta preencher a primeira linha vazia logo abaixo da tabela. Ela está configurada de modo que toda a formatação da linha e fórmulas usadas sejam arrastadas automaticamente para a nova linha.
B10: CADASTRO FORNECEDORES | C10: OBSERVAÇÃO 1 Esta aba faz parte do conjunto de 3 abas para cadastro de informações. Aqui, você pode cadastrar os dados referentes aos seus FORNECEDORES. Esta tabela possui uma Validação de Dados que impede o cadastro de fornecedores duplicados. OBSERVAÇÃO 2 Para cadastrar um novo FORNECEDOR, basta preencher a primeira linha vazia logo abaixo da tabela. Ela está configurada de modo que toda a formatação da linha e fórmulas usadas sejam arrastadas automaticamente para a nova linha.
B13: ENTRADAS | C13: OBSERVAÇÃO 1 Nesta aba você irá registrar todas as ENTRADAS, ou seja, compras para recomposição de estoque. Para cadastrar uma nova ENTRADA de um produto, basta utilizar a Validação de Dados (lista de opções) que se encontra nas células da coluna de PRODUTO. Essa lista se atualiza automaticamente quando você cadastra um novo produto na aba de CADASTRO. OBSERVAÇÃO 2 Para registrar uma nova ENTRADA, basta preencher a primeira linha vazia logo abaixo da tabela. Ela está configurada de modo que toda a formatação da linha e fórmulas usadas sejam arrastadas automaticamente para a nova linha.
B15: SAÍDAS | C15: OBSERVAÇÃO 1 Nesta aba você irá registrar todas as SAÍDAS, ou seja, vendas de produtos. A coluna QUANTIDADE possui uma Validação de Dados que impede que seja registrada uma venda caso não tenha estoque no momento da venda. Obs: Fique atento na coluna de ESTOQUE ACUMULADO, pois a sua venda depende do seu saldo em estoque. Você pode verificar o status de cada produto na aba de CONTROLE DE ESTOQUE, explicada mais abaixo. OBSERVAÇÃO 2 Para cadastrar uma nova SAÍDA de um produto, basta utilizar a Validação de Dados (lista de opções) que se encontra nas células da coluna de PRODUTO. Essa lista se atualiza automaticamente quando você cadastra um novo produto na aba de CADASTRO. OBSERVAÇÃO 3 As colunas de Quantidade Devolvida e Data da Devolução devem ser preenchidas SOMENTE se houver devolução da venda. OBSERVAÇÃO 4 Para registrar uma nova ENTRADA, basta preencher a primeira linha vazia logo abaixo da tabela. Ela está configurada de modo que toda a formatação da linha e fórmulas usadas sejam arrastadas automaticamente para a nova linha.
B17: CONT. ESTOQUE | C17: OBSERVAÇÃO 1 Na aba CONTROLE DE ESTOQUE, a única coluna a ser preenchida manualmente é a de PRODUTO, sempre que um novo produto for adicionado à sua aba de CADASTRO DE PRODUTOS. OBSERVAÇÃO 2 Toda vez que um novo produto for adicionado na aba de CADASTRO DE PRODUTO, a célula F4 da aba CONTROLE DE ESTOQUE apontará que a tabela está defasada. Para corrigir isso, basta adicionar este produto recém-cadastrado também na tabela de CONTROLE DE ESTOQUE. O processo para adicionar um novo produto é o mesmo feito para as outras tabelas: preencher a última linha vazia logo abaixo da tabela. Obs: Preencher somente a coluna de PRODUTO já é suficiente para que todas as fórmulas das demais colunas sejam calculadas! Pronto! Seguindo esse passo a passo a mensagem na célula F4 vai mudar para "Sim!" e a tabela de Controle de Estoque estará 100% atualizada! OBSERVAÇÃO 3 Nesta tabela, você pode verificar a situação atual de estoque de cada um dos seus produtos. Os status possíveis são os seguintes: (a) Estoque Confortável: Você possui estoque suficiente para as vendas daquele produto. A linha daquele produto ficará verde. (b) Estoque Perigoso: Você ainda possui estoque, porém ele está abaixo do mínimo de segurança estabelecido. A linha daquele produto ficará pintada de amarelo. (c) Sem Estoque: Se o seu estoque zerar, esta mensagem aparece e a linha da tabela fica laranja.

Sheet FORN
B1: CADASTRO DE FORNECEDORES | G1: Dúvidas?
B4: PRODUTOS | C4: FORNECEDORES
B6: EMPRESA | C6: CONTATO | D6: E-MAIL | E6: ENDEREÇO | F6: TOTAL COMPRADO
F7: =SUMIF(ENTRADAS!D7:D323,B7,ENTRADAS!H7:H323) -> 0
F8: =SUMIF(ENTRADAS!D8:D324,B8,ENTRADAS!H8:H324) -> 0
F9: =SUMIF(ENTRADAS!D9:D325,B9,ENTRADAS!H9:H325) -> 0
F10: =SUMIF(ENTRADAS!D10:D326,B10,ENTRADAS!H10:H326) -> 0
F11: =SUMIF(ENTRADAS!D11:D327,B11,ENTRADAS!H11:H327) -> 0
F12: =SUMIF(ENTRADAS!D12:D328,B12,ENTRADAS!H12:H328) -> 0
F13: =SUMIF(ENTRADAS!D13:D329,B13,ENTRADAS!H13:H329) -> 0
F14: =SUMIF(ENTRADAS!D14:D330,B14,ENTRADAS!H14:H330) -> 0
F15: =SUMIF(ENTRADAS!D15:D330,B15,ENTRADAS!H15:H330) -> 0
F16: =SUMIF(ENTRADAS!D16:D331,B16,ENTRADAS!H16:H331) -> 0
F17: =SUMIF(ENTRADAS!D17:D332,B17,ENTRADAS!H17:H332) -> 0
F18: =SUMIF(ENTRADAS!D18:D333,B18,ENTRADAS!H18:H333) -> 0
F19: =SUMIF(ENTRADAS!D19:D334,B19,ENTRADAS!H19:H334) -> 0
F20: =SUMIF(ENTRADAS!D20:D335,B20,ENTRADAS!H20:H335) -> 0
F21: =SUMIF(ENTRADAS!D21:D336,B21,ENTRADAS!H21:H336) -> 0
F22: =SUMIF(ENTRADAS!D22:D337,B22,ENTRADAS!H22:H337) -> 0
F23: =SUMIF(ENTRADAS!D23:D338,B23,ENTRADAS!H23:H338) -> 0
F24: =SUMIF(ENTRADAS!D25:D339,B24,ENTRADAS!H25:H339) -> 0
F25: =SUMIF(ENTRADAS!D26:D340,B25,ENTRADAS!H26:H340) -> 0
F26: =SUMIF(ENTRADAS!D27:D341,B26,ENTRADAS!H27:H341) -> 0
F27: =SUMIF(ENTRADAS!D28:D342,B27,ENTRADAS!H28:H342) -> 0
F28: =SUMIF(ENTRADAS!D29:D343,B28,ENTRADAS!H29:H343) -> 0
F29: =SUMIF(ENTRADAS!D30:D344,B29,ENTRADAS!H30:H344) -> 0
F30: =SUMIF(ENTRADAS!D31:D345,B30,ENTRADAS!H31:H345) -> 0
F31: =SUMIF(ENTRADAS!D33:D346,B31,ENTRADAS!H33:H346) -> 0
F32: =SUMIF(ENTRADAS!D34:D347,B32,ENTRADAS!H34:H347) -> 0
F33: =SUMIF(ENTRADAS!D36:D348,B33,ENTRADAS!H36:H348) -> 0
F34: =SUMIF(ENTRADAS!D38:D349,B34,ENTRADAS!H38:H349) -> 0
F35: =SUMIF(ENTRADAS!D40:D350,B35,ENTRADAS!H40:H350) -> 0
F36: =SUMIF(ENTRADAS!D41:D351,B36,ENTRADAS!H41:H351) -> 0
F37: =SUMIF(ENTRADAS!D42:D352,B37,ENTRADAS!H42:H352) -> 0
F38: =SUMIF(ENTRADAS!D43:D353,B38,ENTRADAS!H43:H353) -> 0
F39: =SUMIF(ENTRADAS!D44:D354,B39,ENTRADAS!H44:H354) -> 0
F40: =SUMIF(ENTRADAS!D45:D355,B40,ENTRADAS!H45:H355) -> 0
F41: =SUMIF(ENTRADAS!D46:D356,B41,ENTRADAS!H46:H356) -> 0
F42: =SUMIF(ENTRADAS!D47:D357,B42,ENTRADAS!H47:H357) -> 0
F43: =SUMIF(ENTRADAS!D48:D358,B43,ENTRADAS!H48:H358) -> 0
...

Sheet PROD
B1: CADASTRO DE PRODUTOS | I1: Dúvidas?
B4: PRODUTOS | C4: FORNECEDORES | G4: Instruções
B6: ITEM | C6: CÓDIGO PRÓPRIO | D6: UNIDADE DE MEDIDA | E6: ESTOQUE MÍNIMO | F6: CUSTO UNITÁRIO | G6: PREÇO UNITÁRIO
B7: VT100 | H7: {=IFERROR(INDEX($B$3:$D$14,SMALL(IF($B$3:$B$14=$F$3,ROW($B$3:$B$14)-ROW($B$2)),ROW(1:1)),3),"")} -> 0
B8: VT-266 | C8: 1 | D8: UNIDADE | F8: =AVERAGEIF(ENTRADAS!$C$7:C324,$B8,ENTRADAS!$F$7:F324) -> #DIV/0! | G8: =VLOOKUP(PROD!$B8,ENTRADAS!$C$7:$H$323,5,0) -> 0
B9: VT-258 | C9: 2 | D9: UNIDADE | F9: =AVERAGEIF(ENTRADAS!$C$7:C324,$B9,ENTRADAS!$F$7:F324) -> #DIV/0! | G9: =VLOOKUP(PROD!$B9,ENTRADAS!$C$7:$H$323,5,0) -> 0
B10: VT-250 | C10: 3 | D10: UNIDADE | F10: =AVERAGEIF(ENTRADAS!$C$7:C325,$B10,ENTRADAS!$F$7:F325) -> #DIV/0! | G10: =VLOOKUP(PROD!$B10,ENTRADAS!$C$7:$H$323,5,0) -> 0
B11: VT-242 | C11: 4 | D11: UNIDADE | F11: =AVERAGEIF(ENTRADAS!$C$7:C326,$B11,ENTRADAS!$F$7:F326) -> #DIV/0! | G11: =VLOOKUP(PROD!$B11,ENTRADAS!$C$7:$H$323,5,0) -> 0
B12: VT-234 | C12: 5 | D12: UNIDADE | F12: =AVERAGEIF(ENTRADAS!$C$7:C327,$B12,ENTRADAS!$F$7:F327) -> #DIV/0! | G12: =VLOOKUP(PROD!$B12,ENTRADAS!$C$7:$H$323,5,0) -> 0
B13: VT-226 | C13: 6 | D13: UNIDADE | F13: =AVERAGEIF(ENTRADAS!$C$7:C328,$B13,ENTRADAS!$F$7:F328) -> #DIV/0! | G13: =VLOOKUP(PROD!$B13,ENTRADAS!$C$7:$H$323,5,0) -> 0
B14: VT-218 | C14: 7 | D14: UNIDADE | F14: =AVERAGEIF(ENTRADAS!$C$7:C329,$B14,ENTRADAS!$F$7:F329) -> #DIV/0! | G14: =VLOOKUP(PROD!$B14,ENTRADAS!$C$7:$H$323,5,0) -> 0
B15: - | D15: UNIDADE
B16: VL110LA | D16: UNIDADE
B17: LA-300 | C17: 8 | D17: UNIDADE | F17: =AVERAGEIF(ENTRADAS!$C$7:C330,$B17,ENTRADAS!$F$7:F330) -> #DIV/0! | G17: =VLOOKUP(PROD!$B17,ENTRADAS!$C$7:$H$323,5,0) -> 0
B18: LA-258 | C18: 9 | D18: UNIDADE | F18: =AVERAGEIF(ENTRADAS!$C$7:C331,$B18,ENTRADAS!$F$7:F331) -> #DIV/0! | G18: =VLOOKUP(PROD!$B18,ENTRADAS!$C$7:$H$323,5,0) -> 0
B19: LA-250 | C19: 10 | D19: UNIDADE | F19: =AVERAGEIF(ENTRADAS!$C$7:C332,$B19,ENTRADAS!$F$7:F332) -> #DIV/0! | G19: =VLOOKUP(PROD!$B19,ENTRADAS!$C$7:$H$323,5,0) -> 0
B20: LA-242 | C20: 11 | D20: UNIDADE | F20: =AVERAGEIF(ENTRADAS!$C$7:C333,$B20,ENTRADAS!$F$7:F333) -> #DIV/0! | G20: =VLOOKUP(PROD!$B20,ENTRADAS!$C$7:$H$323,5,0) -> 0
B21: LA-234 | C21: 12 | D21: UNIDADE | F21: =AVERAGEIF(ENTRADAS!$C$7:C334,$B21,ENTRADAS!$F$7:F334) -> #DIV/0! | G21: =VLOOKUP(PROD!$B21,ENTRADAS!$C$7:$H$323,5,0) -> 0
B22: LA-226 | C22: 13 | D22: UNIDADE | F22: =AVERAGEIF(ENTRADAS!$C$7:C335,$B22,ENTRADAS!$F$7:F335) -> #DIV/0! | G22: =VLOOKUP(PROD!$B22,ENTRADAS!$C$7:$H$323,5,0) -> 0
B23: LA-218 | C23: 14 | D23: UNIDADE | F23: =AVERAGEIF(ENTRADAS!$C$7:C336,$B23,ENTRADAS!$F$7:F336) -> #DIV/0! | G23: =VLOOKUP(PROD!$B23,ENTRADAS!$C$7:$H$323,5,0) -> 0
B24: - | D24: UNIDADE
B25: VL110L | D25: UNIDADE
B26: VL-266 | C26: 15 | D26: UNIDADE | F26: =AVERAGEIF(ENTRADAS!$C$7:C336,$B26,ENTRADAS!$F$7:F336) -> #DIV/0! | G26: =VLOOKUP(PROD!$B26,ENTRADAS!$C$7:$H$323,5,0) -> 0
B27: VL-258 | C27: 15 | D27: UNIDADE | F27: =AVERAGEIF(ENTRADAS!$C$7:C337,$B27,ENTRADAS!$F$7:F337) -> #DIV/0! | G27: =VLOOKUP(PROD!$B27,ENTRADAS!$C$7:$H$323,5,0) -> 0
B28: VL-250 | C28: 16 | D28: UNIDADE | F28: =AVERAGEIF(ENTRADAS!$C$7:C338,$B28,ENTRADAS!$F$7:F338) -> #DIV/0! | G28: =VLOOKUP(PROD!$B28,ENTRADAS!$C$7:$H$323,5,0) -> 0
B29: VL-242 | C29: 17 | D29: UNIDADE | F29: =AVERAGEIF(ENTRADAS!$C$7:C339,$B29,ENTRADAS!$F$7:F339) -> #DIV/0! | G29: =VLOOKUP(PROD!$B29,ENTRADAS!$C$7:$H$323,5,0) -> 0
B30: VL-234 | C30: 18 | D30: UNIDADE | F30: =AVERAGEIF(ENTRADAS!$C$7:C340,$B30,ENTRADAS!$F$7:F340) -> #DIV/0! | G30: =VLOOKUP(PROD!$B30,ENTRADAS!$C$7:$H$323,5,0) -> 0
B31: VL-226 | C31: 19 | D31: UNIDADE | F31: =AVERAGEIF(ENTRADAS!$C$7:C341,$B31,ENTRADAS!$F$7:F341) -> #DIV/0! | G31: =VLOOKUP(PROD!$B31,ENTRADAS!$C$7:$H$323,5,0) -> 0
B32: VL-218 | C32: 20 | D32: UNIDADE | F32: =AVERAGEIF(ENTRADAS!$C$7:C342,$B32,ENTRADAS!$F$7:F342) -> #DIV/0! | G32: =VLOOKUP(PROD!$B32,ENTRADAS!$C$7:$H$323,5,0) -> 0
B33: VL-210 | C33: 21 | D33: UNIDADE | F33: =AVERAGEIF(ENTRADAS!$C$7:C343,$B33,ENTRADAS!$F$7:F343) -> #DIV/0! | G33: =VLOOKUP(PROD!$B33,ENTRADAS!$C$7:$H$323,5,0) -> 0
B34: VL-200 | C34: 21 | D34: UNIDADE | F34: =AVERAGEIF(ENTRADAS!$C$7:C344,$B34,ENTRADAS!$F$7:F344) -> #DIV/0! | G34: =VLOOKUP(PROD!$B34,ENTRADAS!$C$7:$H$323,5,0) -> 0
B35: VL-190 | C35: 21 | D35: UNIDADE | F35: =AVERAGEIF(ENTRADAS!$C$7:C345,$B35,ENTRADAS!$F$7:F345) -> #DIV/0! | G35: =VLOOKUP(PROD!$B35,ENTRADAS!$C$7:$H$323,5,0) -> #N/A
B36: VL-180 | C36: 21 | D36: UNIDADE | F36: =AVERAGEIF(ENTRADAS!$C$7:C346,$B36,ENTRADAS!$F$7:F346) -> #DIV/0! | G36: =VLOOKUP(PROD!$B36,ENTRADAS!$C$7:$H$323,5,0) -> 0
B37: - | D37: UNIDADE
B38: VL130 | D38: UNIDADE
B39: 130-258 | C39: 24 | D39: UNIDADE | F39: =AVERAGEIF(ENTRADAS!$C$7:C340,$B39,ENTRADAS!$F$7:F340) -> #DIV/0! | G39: =VLOOKUP(PROD!$B39,ENTRADAS!$C$7:$H$323,5,0) -> 0
B40: 130-250 | C40: 26 | D40: UNIDADE | F40: =AVERAGEIF(ENTRADAS!$C$7:C339,$B40,ENTRADAS!$F$7:F339) -> #DIV/0! | G40: =VLOOKUP(PROD!$B40,ENTRADAS!$C$7:$H$323,5,0) -> 0
B41: 130-242 | C41: 25 | D41: UNIDADE | F41: =AVERAGEIF(ENTRADAS!$C$7:C341,$B41,ENTRADAS!$F$7:F341) -> #DIV/0! | G41: =VLOOKUP(PROD!$B41,ENTRADAS!$C$7:$H$323,5,0) -> 0
B42: 130-234 | C42: 26 | D42: UNIDADE | F42: =AVERAGEIF(ENTRADAS!$C$7:C341,$B42,ENTRADAS!$F$7:F341) -> #DIV/0! | G42: =VLOOKUP(PROD!$B42,ENTRADAS!$C$7:$H$323,5,0) -> 0
B43: 130-226 | C43: 26 | D43: UNIDADE | F43: =AVERAGEIF(ENTRADAS!$C$7:C342,$B43,ENTRADAS!$F$7:F342) -> #DIV/0! | G43: =VLOOKUP(PROD!$B43,ENTRADAS!$C$7:$H$323,5,0) -> 0
...

Sheet ENTRADAS
B1: CONTROLE DE ENTRADAS | J1: Dúvidas?
B6: DATA DA COMPRA | C6: PRODUTO | D6: FORNECEDOR | E6: QUANTIDADE | F6: CUSTO UNITÁRIO | G6: PREÇO DE VENDA | H6: VALOR TOTAL DA COMPRA
B7: 46034 | C7: VT100 | D7: VIPAL | H7: =F7*E7 -> 0
B8: 46034 | C8: VT-266 | D8: VIPAL | E8: 42 | H8: =F8*E8 -> 0
B9: 46034 | C9: VT-258 | D9: VIPAL | E9: 25 | H9: =F9*E9 -> 0
B10: 46034 | C10: VT-250 | D10: VIPAL | E10: 26 | H10: =F10*E10 -> 0
B11: 46034 | C11: VT-242 | D11: VIPAL | E11: 10 | H11: =F11*E11 -> 0
B12: 46034 | C12: VT-234 | D12: VIPAL | E12: 4 | H12: =F12*E12 -> 0
B13: 46034 | C13: VT-226 | D13: VIPAL | H13: =F13*E13 -> 0
B14: 46034 | C14: VT-218 | D14: VIPAL | H14: =F14*E14 -> 0
B15: 46034 | C15: VL110LA | D15: VIPAL | H15: =F15*E15 -> 0
B16: 46034 | C16: LA-300 | D16: VIPAL | H16: =F16*E16 -> 0
B17: 46034 | C17: LA-258 | D17: VIPAL | E17: 6 | H17: =F17*E17 -> 0
B18: 46034 | C18: LA-250 | D18: VIPAL | E18: 13 | H18: =F18*E18 -> 0
B19: 46034 | C19: LA-242 | D19: VIPAL | E19: 122 | H19: =F19*E19 -> 0
B20: 46034 | C20: LA-234 | D20: VIPAL | E20: 154 | H20: =F20*E20 -> 0
B21: 46034 | C21: LA-226 | D21: VIPAL | E21: 38 | H21: =F21*E21 -> 0
B22: 46034 | C22: LA-218 | D22: VIPAL | E22: 19 | H22: =F22*E22 -> 0
B23: 46034 | C23: VL110L | D23: VIPAL | H23: =F23*E23 -> 0
B24: 46034 | C24: VL-266 | D24: VIPAL | E24: 4
B25: 46034 | C25: VL-258 | D25: VIPAL | E25: 4 | H25: =F25*E25 -> 0
B26: 46034 | C26: VL-250 | D26: VIPAL | E26: 24 | H26: =F26*E26 -> 0
B27: 46034 | C27: VL-242 | D27: VIPAL | E27: 40 | H27: =F27*E27 -> 0
B28: 46034 | C28: VL-234 | D28: VIPAL | E28: 47 | H28: =F28*E28 -> 0
B29: 46034 | C29: VL-226 | D29: VIPAL | E29: 25 | H29: =F29*E29 -> 0
B30: 46034 | C30: VL-218 | D30: VIPAL | E30: 7 | H30: =F30*E30 -> 0
B31: 46034 | C31: VL-210 | D31: VIPAL | E31: 1 | H31: =F31*E31 -> 0
B32: 46034 | C32: VL-200 | D32: VIPAL | E32: 1 | H32: =F32*E32 -> 0
B33: 46034 | C33: VL130 | D33: VIPAL | H33: =F33*E33 -> 0
B34: 46034 | C34: 130-258 | D34: VIPAL | E34: 3 | H34: =F34*E34 -> 0
B35: 46034 | C35: 130-250 | D35: VIPAL | E35: 5 | H35: =F35*E35 -> 0
B36: 46034 | C36: 130-242 | D36: VIPAL | E36: 4 | H36: =F36*E36 -> 0
B37: 46034 | C37: 130-234 | D37: VIPAL | E37: 5 | H37: =F37*E37 -> 0
B38: 46034 | C38: 130-226 | D38: VIPAL | E38: 4 | H38: =F38*E38 -> 0
B39: 46034 | C39: 130-218 | D39: VIPAL | E39: 4 | H39: =F39*E39 -> 0
B40: 46034 | C40: VL100 | D40: VIPAL | H40: =F40*E40 -> 0
B41: 46034 | C41: VL100-258 | D41: VIPAL | E41: 6 | H41: =F41*E41 -> 0
B42: 46034 | C42: VL100-250 | D42: VIPAL | E42: 6 | H42: =F42*E42 -> 0
B43: 46034 | C43: VL100-242 | D43: VIPAL | E43: 7 | H43: =F43*E43 -> 0
B44: 46034 | C44: VL100-234 | D44: VIPAL | E44: 9 | H44: =F44*E44 -> 0
...

Sheet SAÍDAS
B1: CONTROLE DE SAÍDAS | M1: Dúvidas?
B6: DATA DE SAIDA | C6: MODELO (BANDAS) | D6: QUANTIDADE | E6: FUNCIONARIO | F6: NF / O.S. | G6: QUANT. DEVOLVIDA | H6: DATA DA DEVOLUÇÃO | I6: PREÇO UNITÁRIO | J6: QUANT. VENDIDA | K6: ESTOQUE ACUMULADO | L6: VALOR TOTAL DA VENDA
B7: 46048 | C7: RAC 44 QUENTE | D7: 2 | E7: MARCOS | J7: =SAÍDAS!$D7-SAÍDAS!$G7 -> 2 | K7: =SUMIFS(ENTRADAS!$E$7:$E$1002,ENTRADAS!$B$7:$B$1002,"<=" & SAÍDAS!$B7,ENTRADAS!$C$7:$C$1002,SAÍDAS!$C7)-SUMIFS(SAÍDAS!$J$7:$J$289,SAÍDAS!$B$7:$B$289,"<=" & SAÍDAS!$B7,SAÍDAS!$C$7:$C$289,SAÍDAS!$C7) -> 79 | L7: =I7*J7 -> 0
B8: 46048 | C8: RAC 40 QUENTE | D8: 6 | E8: MARCOS | J8: =SAÍDAS!$D8-SAÍDAS!$G8 -> 6 | K8: =SUMIFS(ENTRADAS!$E$7:$E$1002,ENTRADAS!$B$7:$B$1002,"<=" & SAÍDAS!$B8,ENTRADAS!$C$7:$C$1002,SAÍDAS!$C8)-SUMIFS(SAÍDAS!$J$7:$J$289,SAÍDAS!$B$7:$B$289,"<=" & SAÍDAS!$B8,SAÍDAS!$C$7:$C$289,SAÍDAS!$C8) -> 55 | L8: =I8*J8 -> 0
B9: 46048 | C9: RAC 25 QUENTE | D9: 1 | E9: MARCOS | J9: =SAÍDAS!$D9-SAÍDAS!$G9 -> 1 | K9: =SUMIFS(ENTRADAS!$E$7:$E$1002,ENTRADAS!$B$7:$B$1002,"<=" & SAÍDAS!$B9,ENTRADAS!$C$7:$C$1002,SAÍDAS!$C9)-SUMIFS(SAÍDAS!$J$7:$J$289,SAÍDAS!$B$7:$B$289,"<=" & SAÍDAS!$B9,SAÍDAS!$C$7:$C$289,SAÍDAS!$C9) -> 12 | L9: =I9*J9 -> 0
B10: 46048 | C10: LA-250 | D10: 3 | E10: POLACO | J10: =SAÍDAS!$D10-SAÍDAS!$G10 -> 3 | K10: =SUMIFS(ENTRADAS!$E$7:$E$1002,ENTRADAS!$B$7:$B$1002,"<=" & SAÍDAS!$B10,ENTRADAS!$C$7:$C$1002,SAÍDAS!$C10)-SUMIFS(SAÍDAS!$J$7:$J$289,SAÍDAS!$B$7:$B$289,"<=" & SAÍDAS!$B10,SAÍDAS!$C$7:$C$289,SAÍDAS!$C10) -> 10 | L10: =I10*J10 -> 0
B11: 46048 | C11: LA-242 | D11: 3 | E11: POLACO | J11: =SAÍDAS!$D11-SAÍDAS!$G11 -> 3 | K11: =SUMIFS(ENTRADAS!$E$7:$E$1002,ENTRADAS!$B$7:$B$1002,"<=" & SAÍDAS!$B11,ENTRADAS!$C$7:$C$1002,SAÍDAS!$C11)-SUMIFS(SAÍDAS!$J$7:$J$289,SAÍDAS!$B$7:$B$289,"<=" & SAÍDAS!$B11,SAÍDAS!$C$7:$C$289,SAÍDAS!$C11) -> 119 | L11: =I11*J11 -> 0
B12: 46048 | C12: LA-234 | D12: 5 | E12: POLACO | J12: =SAÍDAS!$D12-SAÍDAS!$G12 -> 5 | K12: =SUMIFS(ENTRADAS!$E$7:$E$1002,ENTRADAS!$B$7:$B$1002,"<=" & SAÍDAS!$B12,ENTRADAS!$C$7:$C$1002,SAÍDAS!$C12)-SUMIFS(SAÍDAS!$J$7:$J$289,SAÍDAS!$B$7:$B$289,"<=" & SAÍDAS!$B12,SAÍDAS!$C$7:$C$289,SAÍDAS!$C12) -> 149 | L12: =I12*J12 -> 0
B13: 46048 | C13: LA-226 | D13: 1 | E13: POLACO | J13: =SAÍDAS!$D13-SAÍDAS!$G13 -> 1 | K13: =SUMIFS(ENTRADAS!$E$7:$E$1002,ENTRADAS!$B$7:$B$1002,"<=" & SAÍDAS!$B13,ENTRADAS!$C$7:$C$1002,SAÍDAS!$C13)-SUMIFS(SAÍDAS!$J$7:$J$289,SAÍDAS!$B$7:$B$289,"<=" & SAÍDAS!$B13,SAÍDAS!$C$7:$C$289,SAÍDAS!$C13) -> 37 | L13: =I13*J13 -> 0
B14: 46048 | C14: LA-218 | D14: 1 | E14: POLACO | J14: =SAÍDAS!$D14-SAÍDAS!$G14 -> 1 | K14: =SUMIFS(ENTRADAS!$E$7:$E$1002,ENTRADAS!$B$7:$B$1002,"<=" & SAÍDAS!$B14,ENTRADAS!$C$7:$C$1002,SAÍDAS!$C14)-SUMIFS(SAÍDAS!$J$7:$J$289,SAÍDAS!$B$7:$B$289,"<=" & SAÍDAS!$B14,SAÍDAS!$C$7:$C$289,SAÍDAS!$C14) -> 18 | L14: =I14*J14 -> 0
B15: 46048 | C15: VL-242 | D15: 1 | E15: POLACO | J15: =SAÍDAS!$D15-SAÍDAS!$G15 -> 1 | K15: =SUMIFS(ENTRADAS!$E$7:$E$1002,ENTRADAS!$B$7:$B$1002,"<=" & SAÍDAS!$B15,ENTRADAS!$C$7:$C$1002,SAÍDAS!$C15)-SUMIFS(SAÍDAS!$J$7:$J$289,SAÍDAS!$B$7:$B$289,"<=" & SAÍDAS!$B15,SAÍDAS!$C$7:$C$289,SAÍDAS!$C15) -> 39 | L15: =I15*J15 -> 0
B16: 46048 | C16: VL-234 | D16: 2 | E16: POLACO | J16: =SAÍDAS!$D16-SAÍDAS!$G16 -> 2 | K16: =SUMIFS(ENTRADAS!$E$7:$E$1002,ENTRADAS!$B$7:$B$1002,"<=" & SAÍDAS!$B16,ENTRADAS!$C$7:$C$1002,SAÍDAS!$C16)-SUMIFS(SAÍDAS!$J$7:$J$289,SAÍDAS!$B$7:$B$289,"<=" & SAÍDAS!$B16,SAÍDAS!$C$7:$C$289,SAÍDAS!$C16) -> 45 | L16: =I16*J16 -> 0
B17: 46048 | C17: VL-226 | D17: 1 | E17: POLACO | J17: =SAÍDAS!$D17-SAÍDAS!$G17 -> 1 | K17: =SUMIFS(ENTRADAS!$E$7:$E$1002,ENTRADAS!$B$7:$B$1002,"<=" & SAÍDAS!$B17,ENTRADAS!$C$7:$C$1002,SAÍDAS!$C17)-SUMIFS(SAÍDAS!$J$7:$J$289,SAÍDAS!$B$7:$B$289,"<=" & SAÍDAS!$B17,SAÍDAS!$C$7:$C$289,SAÍDAS!$C17) -> 24 | L17: =I17*J17 -> 0
B18: 46048 | C18: VL-266 | D18: 1 | E18: POLACO | J18: =SAÍDAS!$D18-SAÍDAS!$G18 -> 1 | K18: =SUMIFS(ENTRADAS!$E$7:$E$1002,ENTRADAS!$B$7:$B$1002,"<=" & SAÍDAS!$B18,ENTRADAS!$C$7:$C$1002,SAÍDAS!$C18)-SUMIFS(SAÍDAS!$J$7:$J$289,SAÍDAS!$B$7:$B$289,"<=" & SAÍDAS!$B18,SAÍDAS!$C$7:$C$289,SAÍDAS!$C18) -> 3 | L18: =I18*J18 -> 0
... B155: 46055 | C155: PASTA P/MONTAGEM | D155: 1 | E155: AJUSTES | J155: =SAÍDAS!$D155-SAÍDAS!$G155 -> 1 | K155: =SUMIFS(ENTRADAS!$E$7:$E$1002,ENTRADAS!$B$7:$B$1002,"<=" & SAÍDAS!$B155,ENTRADAS!$C$7:$C$1002,SAÍDAS!$C155)-SUMIFS(SAÍDAS!$J$7:$J$289,SAÍDAS!$B$7:$B$289,"<=" & SAÍDAS!$B155,SAÍDAS!$C$7:$C$289,SAÍDAS!$C155) -> 17 | L155: =I155*J155 -> 0
B156: 46055 | C156: VL-258 | D156: 1 | J156: =SAÍDAS!$D156-SAÍDAS!$G156 -> 1 | K156: =SUMIFS(ENTRADAS!$E$7:$E$1002,ENTRADAS!$B$7:$B$1002,"<=" & SAÍDAS!$B156,ENTRADAS!$C$7:$C$1002,SAÍDAS!$C156)-SUMIFS(SAÍDAS!$J$7:$J$289,SAÍDAS!$B$7:$B$289,"<=" & SAÍDAS!$B156,SAÍDAS!$C$7:$C$289,SAÍDAS!$C156) -> 4 | L156: =I156*J156 -> 0
B157: 46055 | C157: VL-250 | D157: 2 | J157: =SAÍDAS!$D157-SAÍDAS!$G157 -> 2 | K157: =SUMIFS(ENTRADAS!$E$7:$E$1002,ENTRADAS!$B$7:$B$1002,"<=" & SAÍDAS!$B157,ENTRADAS!$C$7:$C$1002,SAÍDAS!$C157)-SUMIFS(SAÍDAS!$J$7:$J$289,SAÍDAS!$B$7:$B$289,"<=" & SAÍDAS!$B157,SAÍDAS!$C$7:$C$289,SAÍDAS!$C157) -> 22 | L157: =I157*J157 -> 0
B158: 46055 | C158: VL-242 | D158: 1 | J158: =SAÍDAS!$D158-SAÍDAS!$G158 -> 1 | K158: =SUMIFS(ENTRADAS!$E$7:$E$1002,ENTRADAS!$B$7:$B$1002,"<=" & SAÍDAS!$B158,ENTRADAS!$C$7:$C$1002,SAÍDAS!$C158)-SUMIFS(SAÍDAS!$J$7:$J$289,SAÍDAS!$B$7:$B$289,"<=" & SAÍDAS!$B158,SAÍDAS!$C$7:$C$289,SAÍDAS!$C158) -> 37 | L158: =I158*J158 -> 0
B159: 46055 | C159: VL-234 | D159: 1 | J159: =SAÍDAS!$D159-SAÍDAS!$G159 -> 1 | K159: =SUMIFS(ENTRADAS!$E$7:$E$1002,ENTRADAS!$B$7:$B$1002,"<=" & SAÍDAS!$B159,ENTRADAS!$C$7:$C$1002,SAÍDAS!$C159)-SUMIFS(SAÍDAS!$J$7:$J$289,SAÍDAS!$B$7:$B$289,"<=" & SAÍDAS!$B159,SAÍDAS!$C$7:$C$289,SAÍDAS!$C159) -> 40 | L159: =I159*J159 -> 0
B160: 46055 | C160: LA-242 | D160: 2 | J160: =SAÍDAS!$D160-SAÍDAS!$G160 -> 2 | K160: =SUMIFS(ENTRADAS!$E$7:$E$1002,ENTRADAS!$B$7:$B$1002,"<=" & SAÍDAS!$B160,ENTRADAS!$C$7:$C$1002,SAÍDAS!$C160)-SUMIFS(SAÍDAS!$J$7:$J$289,SAÍDAS!$B$7:$B$289,"<=" & SAÍDAS!$B160,SAÍDAS!$C$7:$C$289,SAÍDAS!$C160) -> 110 | L160: =I160*J160 -> 0
B161: 46055 | C161: LA-218 | D161: 1 | J161: =SAÍDAS!$D161-SAÍDAS!$G161 -> 1 | K161: =SUMIFS(ENTRADAS!$E$7:$E$1002,ENTRADAS!$B$7:$B$1002,"<=" & SAÍDAS!$B161,ENTRADAS!$C$7:$C$1002,SAÍDAS!$C161)-SUMIFS(SAÍDAS!$J$7:$J$289,SAÍDAS!$B$7:$B$289,"<=" & SAÍDAS!$B161,SAÍDAS!$C$7:$C$289,SAÍDAS!$C161) -> 21 | L161: =I161*J161 -> 0
B162: 46055 | C162: VLW-238 | D162: 3 | J162: =SAÍDAS!$D162-SAÍDAS!$G162 -> 3 | K162: =SUMIFS(ENTRADAS!$E$7:$E$1002,ENTRADAS!$B$7:$B$1002,"<=" & SAÍDAS!$B162,ENTRADAS!$C$7:$C$1002,SAÍDAS!$C162)-SUMIFS(SAÍDAS!$J$7:$J$289,SAÍDAS!$B$7:$B$289,"<=" & SAÍDAS!$B162,SAÍDAS!$C$7:$C$289,SAÍDAS!$C162) -> 12 | L162: =I162*J162 -> 0
B163: 46055 | C163: VT-266 | D163: 1 | J163: =SAÍDAS!$D163-SAÍDAS!$G163 -> 1 | K163: =SUMIFS(ENTRADAS!$E$7:$E$1002,ENTRADAS!$B$7:$B$1002,"<=" & SAÍDAS!$B163,ENTRADAS!$C$7:$C$1002,SAÍDAS!$C163)-SUMIFS(SAÍDAS!$J$7:$J$289,SAÍDAS!$B$7:$B$289,"<=" & SAÍDAS!$B163,SAÍDAS!$C$7:$C$289,SAÍDAS!$C163) -> 41 | L163: =I163*J163 -> 0
B164: 46055 | C164: MT-250 | D164: 2 | J164: =SAÍDAS!$D164-SAÍDAS!$G164 -> 2 | K164: =SUMIFS(ENTRADAS!$E$7:$E$1002,ENTRADAS!$B$7:$B$1002,"<=" & SAÍDAS!$B164,ENTRADAS!$C$7:$C$1002,SAÍDAS!$C164)-SUMIFS(SAÍDAS!$J$7:$J$289,SAÍDAS!$B$7:$B$289,"<=" & SAÍDAS!$B164,SAÍDAS!$C$7:$C$289,SAÍDAS!$C164) -> 18 | L164: =I164*J164 -> 0
B165: 46055 | C165: VL10-190 | D165: 1 | J165: =SAÍDAS!$D165-SAÍDAS!$G165 -> 1 | K165: =SUMIFS(ENTRADAS!$E$7:$E$1002,ENTRADAS!$B$7:$B$1002,"<=" & SAÍDAS!$B165,ENTRADAS!$C$7:$C$1002,SAÍDAS!$C165)-SUMIFS(SAÍDAS!$J$7:$J$289,SAÍDAS!$B$7:$B$289,"<=" & SAÍDAS!$B165,SAÍDAS!$C$7:$C$289,SAÍDAS!$C165) -> 6 | L165: =I165*J165 -> 0
B166: 46056 | C166: LA-234 | D166: 19 | E166: FURO | J166: =SAÍDAS!$D166-SAÍDAS!$G166 -> 19 | K166: =SUMIFS(ENTRADAS!$E$7:$E$1002,ENTRADAS!$B$7:$B$1002,"<=" & SAÍDAS!$B166,ENTRADAS!$C$7:$C$1002,SAÍDAS!$C166)-SUMIFS(SAÍDAS!$J$7:$J$289,SAÍDAS!$B$7:$B$289,"<=" & SAÍDAS!$B166,SAÍDAS!$C$7:$C$289,SAÍDAS!$C166) -> 116 | L166: =I166*J166 -> 0
B167: 46056 | C167: LA-250 | D167: 1 | E167: FURO | J167: =SAÍDAS!$D167-SAÍDAS!$G167 -> 1 | K167: =SUMIFS(ENTRADAS!$E$7:$E$1002,ENTRADAS!$B$7:$B$1002,"<=" & SAÍDAS!$B167,ENTRADAS!$C$7:$C$1002,SAÍDAS!$C167)-SUMIFS(SAÍDAS!$J$7:$J$289,SAÍDAS!$B$7:$B$289,"<=" & SAÍDAS!$B167,SAÍDAS!$C$7:$C$289,SAÍDAS!$C167) -> 8 | L167: =I167*J167 -> 0
B168: 46056 | C168: VL-234 | D168: 3 | J168: =SAÍDAS!$D168-SAÍDAS!$G168 -> 3 | K168: =SUMIFS(ENTRADAS!$E$7:$E$1002,ENTRADAS!$B$7:$B$1002,"<=" & SAÍDAS!$B168,ENTRADAS!$C$7:$C$1002,SAÍDAS!$C168)-SUMIFS(SAÍDAS!$J$7:$J$289,SAÍDAS!$B$7:$B$289,"<=" & SAÍDAS!$B168,SAÍDAS!$C$7:$C$289,SAÍDAS!$C168) -> 37 | L168: =I168*J168 -> 0
B169: 46056 | C169: VL-210 | D169: 1 | J169: =SAÍDAS!$D169-SAÍDAS!$G169 -> 1 | K169: =SUMIFS(ENTRADAS!$E$7:$E$1002,ENTRADAS!$B$7:$B$1002,"<=" & SAÍDAS!$B169,ENTRADAS!$C$7:$C$1002,SAÍDAS!$C169)-SUMIFS(SAÍDAS!$J$7:$J$289,SAÍDAS!$B$7:$B$289,"<=" & SAÍDAS!$B169,SAÍDAS!$C$7:$C$289,SAÍDAS!$C169) -> 2 | L169: =I169*J169 -> 0
B170: 46056 | C170: VL100-226 | D170: 1 | J170: =SAÍDAS!$D170-SAÍDAS!$G170 -> 1 | K170: =SUMIFS(ENTRADAS!$E$7:$E$1002,ENTRADAS!$B$7:$B$1002,"<=" & SAÍDAS!$B170,ENTRADAS!$C$7:$C$1002,SAÍDAS!$C170)-SUMIFS(SAÍDAS!$J$7:$J$289,SAÍDAS!$B$7:$B$289,"<=" & SAÍDAS!$B170,SAÍDAS!$C$7:$C$289,SAÍDAS!$C170) -> 7 | L170: =I170*J170 -> 0
B171: 46056 | C171: RM-250 | D171: 1 | J171: =SAÍDAS!$D171-SAÍDAS!$G171 -> 1 | K171: =SUMIFS(ENTRADAS!$E$7:$E$1002,ENTRADAS!$B$7:$B$1002,"<=" & SAÍDAS!$B171,ENTRADAS!$C$7:$C$1002,SAÍDAS!$C171)-SUMIFS(SAÍDAS!$J$7:$J$289,SAÍDAS!$B$7:$B$289,"<=" & SAÍDAS!$B171,SAÍDAS!$C$7:$C$289,SAÍDAS!$C171) -> 4 | L171: =I171*J171 -> 0
B172: 46056 | C172: 510-240 | D172: 2 | J172: =SAÍDAS!$D172-SAÍDAS!$G172 -> 2 | K172: =SUMIFS(ENTRADAS!$E$7:$E$1002,ENTRADAS!$B$7:$B$1002,"<=" & SAÍDAS!$B172,ENTRADAS!$C$7:$C$1002,SAÍDAS!$C172)-SUMIFS(SAÍDAS!$J$7:$J$289,SAÍDAS!$B$7:$B$289,"<=" & SAÍDAS!$B172,SAÍDAS!$C$7:$C$289,SAÍDAS!$C172) -> 9 | L172: =I172*J172 -> 0
B173: 46056 | C173: VRT3-250 | D173: 1 | J173: =SAÍDAS!$D173-SAÍDAS!$G173 -> 1 | K173: =SUMIFS(ENTRADAS!$E$7:$E$1002,ENTRADAS!$B$7:$B$1002,"<=" & SAÍDAS!$B173,ENTRADAS!$C$7:$C$1002,SAÍDAS!$C173)-SUMIFS(SAÍDAS!$J$7:$J$289,SAÍDAS!$B$7:$B$289,"<=" & SAÍDAS!$B173,SAÍDAS!$C$7:$C$289,SAÍDAS!$C173) -> 2 | L173: =I173*J173 -> 0
B174: 46056 | C174: 500B-258 | D174: 1 | J174: =SAÍDAS!$D174-SAÍDAS!$G174 -> 1 | K174: =SUMIFS(ENTRADAS!$E$7:$E$1002,ENTRADAS!$B$7:$B$1002,"<=" & SAÍDAS!$B174,ENTRADAS!$C$7:$C$1002,SAÍDAS!$C174)-SUMIFS(SAÍDAS!$J$7:$J$289,SAÍDAS!$B$7:$B$289,"<=" & SAÍDAS!$B174,SAÍDAS!$C$7:$C$289,SAÍDAS!$C174) -> 3 | L174: =I174*J174 -> 0
B175: 46056 | C175: 500B-250 | D175: 1 | J175: =SAÍDAS!$D175-SAÍDAS!$G175 -> 1 | K175: =SUMIFS(ENTRADAS!$E$7:$E$1002,ENTRADAS!$B$7:$B$1002,"<=" & SAÍDAS!$B175,ENTRADAS!$C$7:$C$1002,SAÍDAS!$C175)-SUMIFS(SAÍDAS!$J$7:$J$289,SAÍDAS!$B$7:$B$289,"<=" & SAÍDAS!$B175,SAÍDAS!$C$7:$C$289,SAÍDAS!$C175) -> 5 | L175: =I175*J175 -> 0
B176: 46056 | C176: VDY-240 | D176: 1 | J176: =SAÍDAS!$D176-SAÍDAS!$G176 -> 1 | K176: =SUMIFS(ENTRADAS!$E$7:$E$1002,ENTRADAS!$B$7:$B$1002,"<=" & SAÍDAS!$B176,ENTRADAS!$C$7:$C$1002,SAÍDAS!$C176)-SUMIFS(SAÍDAS!$J$7:$J$289,SAÍDAS!$B$7:$B$289,"<=" & SAÍDAS!$B176,SAÍDAS!$C$7:$C$289,SAÍDAS!$C176) -> 7 | L176: =I176*J176 -> 0
B177: 46056 | C177: 120L-258 | D177: 20 | J177: =SAÍDAS!$D177-SAÍDAS!$G177 -> 20 | K177: =SUMIFS(ENTRADAS!$E$7:$E$1002,ENTRADAS!$B$7:$B$1002,"<=" & SAÍDAS!$B177,ENTRADAS!$C$7:$C$1002,SAÍDAS!$C177)-SUMIFS(SAÍDAS!$J$7:$J$289,SAÍDAS!$B$7:$B$289,"<=" & SAÍDAS!$B177,SAÍDAS!$C$7:$C$289,SAÍDAS!$C177) -> 16 | L177: =I177*J177 -> 0
B178: 46056 | C178: 120L-242 | D178: 1 | J178: =SAÍDAS!$D178-SAÍDAS!$G178 -> 1 | K178: =SUMIFS(ENTRADAS!$E$7:$E$1002,ENTRADAS!$B$7:$B$1002,"<=" & SAÍDAS!$B178,ENTRADAS!$C$7:$C$1002,SAÍDAS!$C178)-SUMIFS(SAÍDAS!$J$7:$J$289,SAÍDAS!$B$7:$B$289,"<=" & SAÍDAS!$B178,SAÍDAS!$C$7:$C$289,SAÍDAS!$C178) -> 12 | L178: =I178*J178 -> 0
B179: 46056 | C179: 120L-200 | D179: 1 | J179: =SAÍDAS!$D179-SAÍDAS!$G179 -> 1 | K179: =SUMIFS(ENTRADAS!$E$7:$E$1002,ENTRADAS!$B$7:$B$1002,"<=" & SAÍDAS!$B179,ENTRADAS!$C$7:$C$1002,SAÍDAS!$C179)-SUMIFS(SAÍDAS!$J$7:$J$289,SAÍDAS!$B$7:$B$289,"<=" & SAÍDAS!$B179,SAÍDAS!$C$7:$C$289,SAÍDAS!$C179) -> 3 | L179: =I179*J179 -> 0
... B424: 46070 | C424: VLW-238 | D424: 5 | J424: =SAÍDAS!$D424-SAÍDAS!$G424 -> 5 | K424: =SUMIFS(ENTRADAS!$E$7:$E$1002,ENTRADAS!$B$7:$B$1002,"<=" & SAÍDAS!$B424,ENTRADAS!$C$7:$C$1002,SAÍDAS!$C424)-SUMIFS(SAÍDAS!$J$7:$J$289,SAÍDAS!$B$7:$B$289,"<=" & SAÍDAS!$B424,SAÍDAS!$C$7:$C$289,SAÍDAS!$C424) -> 3 | L424: =I424*J424 -> 0
...

Sheet CONT. ESTOQUE
B1: CONTROLE DE ESTOQUE | L1: Dúvidas?
B4: Check automático: A tabela de Controle de Estoque está completa? | F4: =IF(COUNTA('CONT. ESTOQUE'!#REF!)=COUNTA(PROD!$B$7:$B$19),"Sim!","Não! Tabela de Controle de Estoque defasada, acrescentar produto faltante.") -> Não! Tabela de Controle de Estoque defasada, acrescentar produto faltante.
B6: PRODUTOS | C6: ENTRADAS | D6: SAÍDAS | E6: SALDO | F6: ESTOQUE MÍNIMO | G6: STATUS | H6: RECEITA TOTAL | I6: CUSTO TOTAL | J6: LUCRO/PREJUÍZO TOTAL
B7: =PROD!B7 -> VT100 | C7: =IF('CONT. ESTOQUE'!$B7<>"",SUMIF(ENTRADAS!$C$7:$C$1002,'CONT. ESTOQUE'!$B7,ENTRADAS!$E$7:$E$1002),"") -> 0 | D7: =IF('CONT. ESTOQUE'!$B7<>"",SUMIF(SAÍDAS!$C$7:$C$800,'CONT. ESTOQUE'!$B7,SAÍDAS!$J$7:$J$800),"") -> 0 | E7: =IFERROR('CONT. ESTOQUE'!$C7-'CONT. ESTOQUE'!$D7,"") -> 0 | F7: =IFERROR(VLOOKUP('CONT. ESTOQUE'!$B7,PROD!$B$6:$G$1095,4,0),"") -> 0 | G7: =IF('CONT. ESTOQUE'!$B7<>"",IF('CONT. ESTOQUE'!$E7=0,"Sem Estoque",IF('CONT. ESTOQUE'!$E7<'CONT. ESTOQUE'!$F7,"Estoque Perigoso","Estoque Confortável")),"") -> Sem Estoque | H7: =SUMIF(SAÍDAS!$C$7:$C$289,'CONT. ESTOQUE'!$B7,SAÍDAS!$L$7:$L$289) -> 0 | I7: =SUMIF(ENTRADAS!$C$8:$C$1002,'CONT. ESTOQUE'!$B7,ENTRADAS!$H$7:$H$1002) -> 0 | J7: ='CONT. ESTOQUE'!$H7-'CONT. ESTOQUE'!$I7 -> 0
B8: =PROD!B8 -> VT-266 | C8: 40 | D8: =IF('CONT. ESTOQUE'!$B8<>"",SUMIF(SAÍDAS!$C$7:$C$800,'CONT. ESTOQUE'!$B8,SAÍDAS!$J$7:$J$800),"") -> 12 | E8: =IFERROR('CONT. ESTOQUE'!$C8-'CONT. ESTOQUE'!$D8,"") -> 28 | F8: =IFERROR(VLOOKUP('CONT. ESTOQUE'!$B8,PROD!$B$6:$G$1095,4,0),"") -> 0 | G8: =IF('CONT. ESTOQUE'!$B8<>"",IF('CONT. ESTOQUE'!$E8=0,"Sem Estoque",IF('CONT. ESTOQUE'!$E8<'CONT. ESTOQUE'!$F8,"Estoque Perigoso","Estoque Confortável")),"") -> Estoque Confortável | H8: =SUMIF(SAÍDAS!$C$7:$C$289,'CONT. ESTOQUE'!$B8,SAÍDAS!$L$7:$L$289) -> 0 | I8: =SUMIF(ENTRADAS!$C$8:$C$1002,'CONT. ESTOQUE'!$B8,ENTRADAS!$H$7:$H$1002) -> 0 | J8: ='CONT. ESTOQUE'!$H8-'CONT. ESTOQUE'!$I8 -> 0
B9: =PROD!B9 -> VT-258 | C9: 13 | D9: =IF('CONT. ESTOQUE'!$B9<>"",SUMIF(SAÍDAS!$C$7:$C$800,'CONT. ESTOQUE'!$B9,SAÍDAS!$J$7:$J$800),"") -> 6 | E9: =IFERROR('CONT. ESTOQUE'!$C9-'CONT. ESTOQUE'!$D9,"") -> 7 | F9: =IFERROR(VLOOKUP('CONT. ESTOQUE'!$B9,PROD!$B$6:$G$1095,4,0),"") -> 0 | G9: =IF('CONT. ESTOQUE'!$B9<>"",IF('CONT. ESTOQUE'!$E9=0,"Sem Estoque",IF('CONT. ESTOQUE'!$E9<'CONT. ESTOQUE'!$F9,"Estoque Perigoso","Estoque Confortável")),"") -> Estoque Confortável | H9: =SUMIF(SAÍDAS!$C$7:$C$289,'CONT. ESTOQUE'!$B9,SAÍDAS!$L$7:$L$289) -> 0 | I9: =SUMIF(ENTRADAS!$C$8:$C$1002,'CONT. ESTOQUE'!$B9,ENTRADAS!$H$7:$H$1002) -> 0 | J9: ='CONT. ESTOQUE'!$H9-'CONT. ESTOQUE'!$I9 -> 0
B10: =PROD!B10 -> VT-250 | C10: =IF('CONT. ESTOQUE'!$B10<>"",SUMIF(ENTRADAS!$C$7:$C$1002,'CONT. ESTOQUE'!$B10,ENTRADAS!$E$7:$E$1002),"") -> 26 | D10: =IF('CONT. ESTOQUE'!$B10<>"",SUMIF(SAÍDAS!$C$7:$C$800,'CONT. ESTOQUE'!$B10,SAÍDAS!$J$7:$J$800),"") -> 9 | E10: =IFERROR('CONT. ESTOQUE'!$C10-'CONT. ESTOQUE'!$D10,"") -> 17 | F10: =IFERROR(VLOOKUP('CONT. ESTOQUE'!$B10,PROD!$B$6:$G$1095,4,0),"") -> 0 | G10: =IF('CONT. ESTOQUE'!$B10<>"",IF('CONT. ESTOQUE'!$E10=0,"Sem Estoque",IF('CONT. ESTOQUE'!$E10<'CONT. ESTOQUE'!$F10,"Estoque Perigoso","Estoque Confortável")),"") -> Estoque Confortável | H10: =SUMIF(SAÍDAS!$C$7:$C$289,'CONT. ESTOQUE'!$B10,SAÍDAS!$L$7:$L$289) -> 0 | I10: =SUMIF(ENTRADAS!$C$8:$C$1002,'CONT. ESTOQUE'!$B10,ENTRADAS!$H$7:$H$1002) -> 0 | J10: ='CONT. ESTOQUE'!$H10-'CONT. ESTOQUE'!$I10 -> 0
B11: =PROD!B11 -> VT-242 | C11: 9 | D11: =IF('CONT. ESTOQUE'!$B11<>"",SUMIF(SAÍDAS!$C$7:$C$800,'CONT. ESTOQUE'!$B11,SAÍDAS!$J$7:$J$800),"") -> 2 | E11: =IFERROR('CONT. ESTOQUE'!$C11-'CONT. ESTOQUE'!$D11,"") -> 7 | F11: =IFERROR(VLOOKUP('CONT. ESTOQUE'!$B11,PROD!$B$6:$G$1095,4,0),"") -> 0 | G11: =IF('CONT. ESTOQUE'!$B11<>"",IF('CONT. ESTOQUE'!$E11=0,"Sem Estoque",IF('CONT. ESTOQUE'!$E11<'CONT. ESTOQUE'!$F11,"Estoque Perigoso","Estoque Confortável")),"") -> Estoque Confortável | H11: =SUMIF(SAÍDAS!$C$7:$C$289,'CONT. ESTOQUE'!$B11,SAÍDAS!$L$7:$L$289) -> 0 | I11: =SUMIF(ENTRADAS!$C$8:$C$1002,'CONT. ESTOQUE'!$B11,ENTRADAS!$H$7:$H$1002) -> 0 | J11: ='CONT. ESTOQUE'!$H11-'CONT. ESTOQUE'!$I11 -> 0
B12: =PROD!B12 -> VT-234 | C12: 5 | D12: =IF('CONT. ESTOQUE'!$B12<>"",SUMIF(SAÍDAS!$C$7:$C$800,'CONT. ESTOQUE'!$B12,SAÍDAS!$J$7:$J$800),"") -> 1 | E12: =IFERROR('CONT. ESTOQUE'!$C12-'CONT. ESTOQUE'!$D12,"") -> 4 | F12: =IFERROR(VLOOKUP('CONT. ESTOQUE'!$B12,PROD!$B$6:$G$1095,4,0),"") -> 0 | G12: =IF('CONT. ESTOQUE'!$B12<>"",IF('CONT. ESTOQUE'!$E12=0,"Sem Estoque",IF('CONT. ESTOQUE'!$E12<'CONT. ESTOQUE'!$F12,"Estoque Perigoso","Estoque Confortável")),"") -> Estoque Confortável | H12: =SUMIF(SAÍDAS!$C$7:$C$289,'CONT. ESTOQUE'!$B12,SAÍDAS!$L$7:$L$289) -> 0 | I12: =SUMIF(ENTRADAS!$C$8:$C$1002,'CONT. ESTOQUE'!$B12,ENTRADAS!$H$7:$H$1002) -> 0 | J12: ='CONT. ESTOQUE'!$H12-'CONT. ESTOQUE'!$I12 -> 0
B13: =PROD!B13 -> VT-226 | C13: =IF('CONT. ESTOQUE'!$B13<>"",SUMIF(ENTRADAS!$C$7:$C$1002,'CONT. ESTOQUE'!$B13,ENTRADAS!$E$7:$E$1002),"") -> 0 | D13: =IF('CONT. ESTOQUE'!$B13<>"",SUMIF(SAÍDAS!$C$7:$C$800,'CONT. ESTOQUE'!$B13,SAÍDAS!$J$7:$J$800),"") -> 1 | E13: =IFERROR('CONT. ESTOQUE'!$C13-'CONT. ESTOQUE'!$D13,"") -> -1 | F13: =IFERROR(VLOOKUP('CONT. ESTOQUE'!$B13,PROD!$B$6:$G$1095,4,0),"") -> 0 | G13: =IF('CONT. ESTOQUE'!$B13<>"",IF('CONT. ESTOQUE'!$E13=0,"Sem Estoque",IF('CONT. ESTOQUE'!$E13<'CONT. ESTOQUE'!$F13,"Estoque Perigoso","Estoque Confortável")),"") -> Estoque Perigoso | H13: =SUMIF(SAÍDAS!$C$7:$C$289,'CONT. ESTOQUE'!$B13,SAÍDAS!$L$7:$L$289) -> 0 | I13: =SUMIF(ENTRADAS!$C$8:$C$1002,'CONT. ESTOQUE'!$B13,ENTRADAS!$H$7:$H$1002) -> 0 | J13: ='CONT. ESTOQUE'!$H13-'CONT. ESTOQUE'!$I13 -> 0
B14: =PROD!B14 -> VT-218 | C14: =IF('CONT. ESTOQUE'!$B14<>"",SUMIF(ENTRADAS!$C$7:$C$1002,'CONT. ESTOQUE'!$B14,ENTRADAS!$E$7:$E$1002),"") -> 0 | D14: =IF('CONT. ESTOQUE'!$B14<>"",SUMIF(SAÍDAS!$C$7:$C$800,'CONT. ESTOQUE'!$B14,SAÍDAS!$J$7:$J$800),"") -> 0 | E14: =IFERROR('CONT. ESTOQUE'!$C14-'CONT. ESTOQUE'!$D14,"") -> 0 | F14: =IFERROR(VLOOKUP('CONT. ESTOQUE'!$B14,PROD!$B$6:$G$1095,4,0),"") -> 0 | G14: =IF('CONT. ESTOQUE'!$B14<>"",IF('CONT. ESTOQUE'!$E14=0,"Sem Estoque",IF('CONT. ESTOQUE'!$E14<'CONT. ESTOQUE'!$F14,"Estoque Perigoso","Estoque Confortável")),"") -> Sem Estoque | H14: =SUMIF(SAÍDAS!$C$7:$C$289,'CONT. ESTOQUE'!$B14,SAÍDAS!$L$7:$L$289) -> 0 | I14: =SUMIF(ENTRADAS!$C$8:$C$1002,'CONT. ESTOQUE'!$B14,ENTRADAS!$H$7:$H$1002) -> 0 | J14: ='CONT. ESTOQUE'!$H14-'CONT. ESTOQUE'!$I14 -> 0
B15: =PROD!B15 -> - | C15: =IF('CONT. ESTOQUE'!$B15<>"",SUMIF(ENTRADAS!$C$7:$C$1002,'CONT. ESTOQUE'!$B15,ENTRADAS!$E$7:$E$1002),"") -> 0 | D15: =IF('CONT. ESTOQUE'!$B15<>"",SUMIF(SAÍDAS!$C$7:$C$800,'CONT. ESTOQUE'!$B15,SAÍDAS!$J$7:$J$800),"") -> 0 | E15: =IFERROR('CONT. ESTOQUE'!$C15-'CONT. ESTOQUE'!$D15,"") -> 0 | F15: =IFERROR(VLOOKUP('CONT. ESTOQUE'!$B15,PROD!$B$6:$G$1095,4,0),"") -> 0 | G15: =IF('CONT. ESTOQUE'!$B15<>"",IF('CONT. ESTOQUE'!$E15=0,"Sem Estoque",IF('CONT. ESTOQUE'!$E15<'CONT. ESTOQUE'!$F15,"Estoque Perigoso","Estoque Confortável")),"") -> Sem Estoque | H15: =SUMIF(SAÍDAS!$C$7:$C$289,'CONT. ESTOQUE'!$B15,SAÍDAS!$L$7:$L$289) -> 0 | I15: =SUMIF(ENTRADAS!$C$8:$C$1002,'CONT. ESTOQUE'!$B15,ENTRADAS!$H$7:$H$1002) -> 0 | J15: ='CONT. ESTOQUE'!$H15-'CONT. ESTOQUE'!$I15 -> 0
B16: =PROD!B16 -> VL110LA | C16: =IF('CONT. ESTOQUE'!$B16<>"",SUMIF(ENTRADAS!$C$7:$C$1002,'CONT. ESTOQUE'!$B16,ENTRADAS!$E$7:$E$1002),"") -> 0 | D16: =IF('CONT. ESTOQUE'!$B16<>"",SUMIF(SAÍDAS!$C$7:$C$800,'CONT. ESTOQUE'!$B16,SAÍDAS!$J$7:$J$800),"") -> 0 | E16: =IFERROR('CONT. ESTOQUE'!$C16-'CONT. ESTOQUE'!$D16,"") -> 0 | F16: =IFERROR(VLOOKUP('CONT. ESTOQUE'!$B16,PROD!$B$6:$G$1095,4,0),"") -> 0 | G16: =IF('CONT. ESTOQUE'!$B16<>"",IF('CONT. ESTOQUE'!$E16=0,"Sem Estoque",IF('CONT. ESTOQUE'!$E16<'CONT. ESTOQUE'!$F16,"Estoque Perigoso","Estoque Confortável")),"") -> Sem Estoque | H16: =SUMIF(SAÍDAS!$C$7:$C$289,'CONT. ESTOQUE'!$B16,SAÍDAS!$L$7:$L$289) -> 0 | I16: =SUMIF(ENTRADAS!$C$8:$C$1002,'CONT. ESTOQUE'!$B16,ENTRADAS!$H$7:$H$1002) -> 0 | J16: ='CONT. ESTOQUE'!$H16-'CONT. ESTOQUE'!$I16 -> 0
B17: =PROD!B17 -> LA-300 | C17: =IF('CONT. ESTOQUE'!$B17<>"",SUMIF(ENTRADAS!$C$7:$C$1002,'CONT. ESTOQUE'!$B17,ENTRADAS!$E$7:$E$1002),"") -> 2 | D17: =IF('CONT. ESTOQUE'!$B17<>"",SUMIF(SAÍDAS!$C$7:$C$800,'CONT. ESTOQUE'!$B17,SAÍDAS!$J$7:$J$800),"") -> 0 | E17: =IFERROR('CONT. ESTOQUE'!$C17-'CONT. ESTOQUE'!$D17,"") -> 2 | F17: =IFERROR(VLOOKUP('CONT. ESTOQUE'!$B17,PROD!$B$6:$G$1095,4,0),"") -> 0 | G17: =IF('CONT. ESTOQUE'!$B17<>"",IF('CONT. ESTOQUE'!$E17=0,"Sem Estoque",IF('CONT. ESTOQUE'!$E17<'CONT. ESTOQUE'!$F17,"Estoque Perigoso","Estoque Confortável")),"") -> Estoque Confortável | H17: =SUMIF(SAÍDAS!$C$7:$C$289,'CONT. ESTOQUE'!$B17,SAÍDAS!$L$7:$L$289) -> 0 | I17: =SUMIF(ENTRADAS!$C$8:$C$1002,'CONT. ESTOQUE'!$B17,ENTRADAS!$H$7:$H$1002) -> 0 | J17: ='CONT. ESTOQUE'!$H17-'CONT. ESTOQUE'!$I17 -> 0
B18: =PROD!B18 -> LA-258 | C18: =IF('CONT. ESTOQUE'!$B18<>"",SUMIF(ENTRADAS!$C$7:$C$1002,'CONT. ESTOQUE'!$B18,ENTRADAS!$E$7:$E$1002),"") -> 6 | D18: =IF('CONT. ESTOQUE'!$B18<>"",SUMIF(SAÍDAS!$C$7:$C$800,'CONT. ESTOQUE'!$B18,SAÍDAS!$J$7:$J$800),"") -> 0 | E18: =IFERROR('CONT. ESTOQUE'!$C18-'CONT. ESTOQUE'!$D18,"") -> 6 | F18: =IFERROR(VLOOKUP('CONT. ESTOQUE'!$B18,PROD!$B$6:$G$1095,4,0),"") -> 0 | G18: =IF('CONT. ESTOQUE'!$B18<>"",IF('CONT. ESTOQUE'!$E18=0,"Sem Estoque",IF('CONT. ESTOQUE'!$E18<'CONT. ESTOQUE'!$F18,"Estoque Perigoso","Estoque Confortável")),"") -> Estoque Confortável | H18: =SUMIF(SAÍDAS!$C$7:$C$289,'CONT. ESTOQUE'!$B18,SAÍDAS!$L$7:$L$289) -> 0 | I18: =SUMIF(ENTRADAS!$C$8:$C$1002,'CONT. ESTOQUE'!$B18,ENTRADAS!$H$7:$H$1002) -> 0 | J18: ='CONT. ESTOQUE'!$H18-'CONT. ESTOQUE'!$I18 -> 0
B19: =PROD!B19 -> LA-250 | C19: =IF('CONT. ESTOQUE'!$B19<>"",SUMIF(ENTRADAS!$C$7:$C$1002,'CONT. ESTOQUE'!$B19,ENTRADAS!$E$7:$E$1002),"") -> 13 | D19: =IF('CONT. ESTOQUE'!$B19<>"",SUMIF(SAÍDAS!$C$7:$C$800,'CONT. ESTOQUE'!$B19,SAÍDAS!$J$7:$J$800),"") -> 12 | E19: =IFERROR('CONT. ESTOQUE'!$C19-'CONT. ESTOQUE'!$D19,"") -> 1 | F19: =IFERROR(VLOOKUP('CONT. ESTOQUE'!$B19,PROD!$B$6:$G$1095,4,0),"") -> 0 | G19: =IF('CONT. ESTOQUE'!$B19<>"",IF('CONT. ESTOQUE'!$E19=0,"Sem Estoque",IF('CONT. ESTOQUE'!$E19<'CONT. ESTOQUE'!$F19,"Estoque Perigoso","Estoque Confortável")),"") -> Estoque Confortável | H19: =SUMIF(SAÍDAS!$C$7:$C$289,'CONT. ESTOQUE'!$B19,SAÍDAS!$L$7:$L$289) -> 0 | I19: =SUMIF(ENTRADAS!$C$8:$C$1002,'CONT. ESTOQUE'!$B19,ENTRADAS!$H$7:$H$1002) -> 0 | J19: ='CONT. ESTOQUE'!$H19-'CONT. ESTOQUE'!$I19 -> 0
B20: =PROD!B20 -> LA-242 | C20: =IF('CONT. ESTOQUE'!$B20<>"",SUMIF(ENTRADAS!$C$7:$C$1002,'CONT. ESTOQUE'!$B20,ENTRADAS!$E$7:$E$1002),"") -> 122 | D20: =IF('CONT. ESTOQUE'!$B20<>"",SUMIF(SAÍDAS!$C$7:$C$800,'CONT. ESTOQUE'!$B20,SAÍDAS!$J$7:$J$800),"") -> 32 | E20: =IFERROR('CONT. ESTOQUE'!$C20-'CONT. ESTOQUE'!$D20,"") -> 90 | F20: =IFERROR(VLOOKUP('CONT. ESTOQUE'!$B20,PROD!$B$6:$G$1095,4,0),"") -> 0 | G20: =IF('CONT. ESTOQUE'!$B20<>"",IF('CONT. ESTOQUE'!$E20=0,"Sem Estoque",IF('CONT. ESTOQUE'!$E20<'CONT. ESTOQUE'!$F20,"Estoque Perigoso","Estoque Confortável")),"") -> Estoque Confortável | H20: =SUMIF(SAÍDAS!$C$7:$C$289,'CONT. ESTOQUE'!$B20,SAÍDAS!$L$7:$L$289) -> 0 | I20: =SUMIF(ENTRADAS!$C$8:$C$1002,'CONT. ESTOQUE'!$B20,ENTRADAS!$H$7:$H$1002) -> 0 | J20: ='CONT. ESTOQUE'!$H20-'CONT. ESTOQUE'!$I20 -> 0
B21: =PROD!B21 -> LA-234 | C21: =IF('CONT. ESTOQUE'!$B21<>"",SUMIF(ENTRADAS!$C$7:$C$1002,'CONT. ESTOQUE'!$B21,ENTRADAS!$E$7:$E$1002),"") -> 154 | D21: =IF('CONT. ESTOQUE'!$B21<>"",SUMIF(SAÍDAS!$C$7:$C$800,'CONT. ESTOQUE'!$B21,SAÍDAS!$J$7:$J$800),"") -> 65 | E21: =IFERROR('CONT. ESTOQUE'!$C21-'CONT. ESTOQUE'!$D21,"") -> 89 | F21: =IFERROR(VLOOKUP('CONT. ESTOQUE'!$B21,PROD!$B$6:$G$1095,4,0),"") -> 0 | G21: =IF('CONT. ESTOQUE'!$B21<>"",IF('CONT. ESTOQUE'!$E21=0,"Sem Estoque",IF('CONT. ESTOQUE'!$E21<'CONT. ESTOQUE'!$F21,"Estoque Perigoso","Estoque Confortável")),"") -> Estoque Confortável | H21: =SUMIF(SAÍDAS!$C$7:$C$289,'CONT. ESTOQUE'!$B21,SAÍDAS!$L$7:$L$289) -> 0 | I21: =SUMIF(ENTRADAS!$C$8:$C$1002,'CONT. ESTOQUE'!$B21,ENTRADAS!$H$7:$H$1002) -> 0 | J21: ='CONT. ESTOQUE'!$H21-'CONT. ESTOQUE'!$I21 -> 0
B22: =PROD!B22 -> LA-226 | C22: =IF('CONT. ESTOQUE'!$B22<>"",SUMIF(ENTRADAS!$C$7:$C$1002,'CONT. ESTOQUE'!$B22,ENTRADAS!$E$7:$E$1002),"") -> 47 | D22: =IF('CONT. ESTOQUE'!$B22<>"",SUMIF(SAÍDAS!$C$7:$C$800,'CONT. ESTOQUE'!$B22,SAÍDAS!$J$7:$J$800),"") -> 21 | E22: =IFERROR('CONT. ESTOQUE'!$C22-'CONT. ESTOQUE'!$D22,"") -> 26 | F22: =IFERROR(VLOOKUP('CONT. ESTOQUE'!$B22,PROD!$B$6:$G$1095,4,0),"") -> 0 | G22: =IF('CONT. ESTOQUE'!$B22<>"",IF('CONT. ESTOQUE'!$E22=0,"Sem Estoque",IF('CONT. ESTOQUE'!$E22<'CONT. ESTOQUE'!$F22,"Estoque Perigoso","Estoque Confortável")),"") -> Estoque Confortável | H22: =SUMIF(SAÍDAS!$C$7:$C$289,'CONT. ESTOQUE'!$B22,SAÍDAS!$L$7:$L$289) -> 0 | I22: =SUMIF(ENTRADAS!$C$8:$C$1002,'CONT. ESTOQUE'!$B22,ENTRADAS!$H$7:$H$1002) -> 0 | J22: ='CONT. ESTOQUE'!$H22-'CONT. ESTOQUE'!$I22 -> 0
B23: =PROD!B23 -> LA-218 | C23: =IF('CONT. ESTOQUE'!$B23<>"",SUMIF(ENTRADAS!$C$7:$C$1002,'CONT. ESTOQUE'!$B23,ENTRADAS!$E$7:$E$1002),"") -> 29 | D23: =IF('CONT. ESTOQUE'!$B23<>"",SUMIF(SAÍDAS!$C$7:$C$800,'CONT. ESTOQUE'!$B23,SAÍDAS!$J$7:$J$800),"") -> 28 | E23: =IFERROR('CONT. ESTOQUE'!$C23-'CONT. ESTOQUE'!$D23,"") -> 1 | F23: =IFERROR(VLOOKUP('CONT. ESTOQUE'!$B23,PROD!$B$6:$G$1095,4,0),"") -> 0 | G23: =IF('CONT. ESTOQUE'!$B23<>"",IF('CONT. ESTOQUE'!$E23=0,"Sem Estoque",IF('CONT. ESTOQUE'!$E23<'CONT. ESTOQUE'!$F23,"Estoque Perigoso","Estoque Confortável")),"") -> Estoque Confortável | H23: =SUMIF(SAÍDAS!$C$7:$C$289,'CONT. ESTOQUE'!$B23,SAÍDAS!$L$7:$L$289) -> 0 | I23: =SUMIF(ENTRADAS!$C$8:$C$1002,'CONT. ESTOQUE'!$B23,ENTRADAS!$H$7:$H$1002) -> 0 | J23: ='CONT. ESTOQUE'!$H23-'CONT. ESTOQUE'!$I23 -> 0
B24: =PROD!B24 -> - | C24: =IF('CONT. ESTOQUE'!$B24<>"",SUMIF(ENTRADAS!$C$7:$C$1002,'CONT. ESTOQUE'!$B24,ENTRADAS!$E$7:$E$1002),"") -> 0 | D24: =IF('CONT. ESTOQUE'!$B24<>"",SUMIF(SAÍDAS!$C$7:$C$800,'CONT. ESTOQUE'!$B24,SAÍDAS!$J$7:$J$800),"") -> 0 | E24: =IFERROR('CONT. ESTOQUE'!$C24-'CONT. ESTOQUE'!$D24,"") -> 0 | F24: =IFERROR(VLOOKUP('CONT. ESTOQUE'!$B24,PROD!$B$6:$G$1095,4,0),"") -> 0 | G24: =IF('CONT. ESTOQUE'!$B24<>"",IF('CONT. ESTOQUE'!$E24=0,"Sem Estoque",IF('CONT. ESTOQUE'!$E24<'CONT. ESTOQUE'!$F24,"Estoque Perigoso","Estoque Confortável")),"") -> Sem Estoque | H24: =SUMIF(SAÍDAS!$C$7:$C$289,'CONT. ESTOQUE'!$B24,SAÍDAS!$L$7:$L$289) -> 0 | I24: =SUMIF(ENTRADAS!$C$8:$C$1002,'CONT. ESTOQUE'!$B24,ENTRADAS!$H$7:$H$1002) -> 0 | J24: ='CONT. ESTOQUE'!$H24-'CONT. ESTOQUE'!$I24 -> 0
... B495: =PROD!B495 -> 0 | C495: =IF('CONT. ESTOQUE'!$B495<>"",SUMIF(ENTRADAS!$C$7:$C$1002,'CONT. ESTOQUE'!$B495,ENTRADAS!$E$7:$E$1002),"") -> 0 | D495: =IF('CONT. ESTOQUE'!$B495<>"",SUMIF(SAÍDAS!$C$7:$C$800,'CONT. ESTOQUE'!$B495,SAÍDAS!$J$7:$J$800),"") -> 0 | E495: =IFERROR('CONT. ESTOQUE'!$C495-'CONT. ESTOQUE'!$D495,"") -> 0 | F495: =IFERROR(VLOOKUP('CONT. ESTOQUE'!$B495,PROD!$B$6:$G$1095,4,0),"") | G495: =IF('CONT. ESTOQUE'!$B495<>"",IF('CONT. ESTOQUE'!$E495=0,"Sem Estoque",IF('CONT. ESTOQUE'!$E495<'CONT. ESTOQUE'!$F495,"Estoque Perigoso","Estoque Confortável")),"") -> Sem Estoque | H495: =SUMIF(SAÍDAS!$C$7:$C$289,'CONT. ESTOQUE'!$B495,SAÍDAS!$L$7:$L$289) -> 0 | I495: =SUMIF(ENTRADAS!$C$8:$C$1002,'CONT. ESTOQUE'!$B495,ENTRADAS!$H$7:$H$1002) -> 0 | J495: ='CONT. ESTOQUE'!$H495-'CONT. ESTOQUE'!$I495 -> 0

Sheet OBS
B2: Colunas1 | C2: Colunas2 | D2: Colunas3 | E2: Colunas4 | F2: Colunas5 | G2: Colunas6 | H2: Colunas7 | I2: Colunas8
B3: OBSERVAÇÕES

Sheet Plan1
A1: VT100 | B1: 0
A2: VT-266 | B2: 42
A3: VT-258 | B3: 22
A4: VT-250 | B4: 23
A5: VT-242 | B5: 9
A6: VT-234 | B6: 3
A7: VT-226 | B7: 0
A8: VT-218 | B8: 0
A9: - | B9: 0
A10: VL110LA | B10: 0
A11: LA-300 | B11: 2
A12: LA-258 | B12: 6
... A287: CAMELBEC | B287: 1

Sheet Plan2
